<?xml version="1.0"?>
<robot name="turtlebot3_waffle" xmlns:xacro="http://ros.org/wiki/xacro">
  <!-- <xacro:include filename="$(find turtlebot3_description)/urdf/common_properties.urdf"/>

  <xacro:property name="r200_cam_rgb_px" value="0.005"/>
  <xacro:property name="r200_cam_rgb_py" value="0.018"/>
  <xacro:property name="r200_cam_rgb_pz" value="0.013"/>
  <xacro:property name="r200_cam_depth_offset" value="0.01"/> -->

  <!-- Init colour -->
  <material name="black">
    <color rgba="0.0 0.0 0.0 1.0" />
  </material>

  <material name="dark">
    <color rgba="0.3 0.3 0.3 1.0" />
  </material>

  <material name="light_black">
    <color rgba="0.4 0.4 0.4 1.0" />
  </material>

  <material name="blue">
    <color rgba="0.0 0.0 0.8 1.0" />
  </material>

  <material name="green">
    <color rgba="0.0 0.8 0.0 1.0" />
  </material>

  <material name="grey">
    <color rgba="0.5 0.5 0.5 1.0" />
  </material>

  <material name="orange">
    <color rgba="1.0 0.4235 0.0392 1.0" />
  </material>

  <material name="brown">
    <color rgba="0.8706 0.8118 0.7647 1.0" />
  </material>

  <material name="red">
    <color rgba="0.8 0.0 0.0 1.0" />
  </material>

  <material name="white">
    <color rgba="1.0 1.0 1.0 1.0" />
  </material>

  <link name="base_footprint" />

  <joint name="base_joint" type="fixed">
    <parent link="base_footprint" />
    <child link="base_link" />
    <origin xyz="0 0 0.54" rpy="0 0 0" />
  </joint>

  <!-- base link -->
  <link name="base_link">
    <visual>
      <origin xyz="0 0 0.0" rpy="0 0 0" />
      <geometry>
        <box size="1.18 0.6 0.65" />
      </geometry>
      <material name="blue">
        <color rgba="0.1 0.1 1.0 0.5" />
      </material>
    </visual>
    <collision>
      <origin xyz="0 0 0" rpy="0 0 0" />
      <geometry>
        <box size="1.18 0.6 0.65" />
      </geometry>
    </collision>
  </link>

  <!-- laser joint -->
  <joint name="laser_joint" type="fixed">
    <parent link="base_link" />
    <child link="laser_link" />
    <origin xyz="0.0 0.2 0.1" />
  </joint>

  <!-- laser link -->
  <link name="laser_link">
    <visual>
      <origin xyz="0 0 0" rpy="0 0 0" />
      <geometry>
        <cylinder length="0.02" radius="0.02" />
      </geometry>
      <material name="black">
        <color rgba="0.0 0.0 0.0 0.5" />
      </material>
    </visual>
  </link>

  <!-- imu joint -->
  <joint name="imu_joint" type="fixed">
    <parent link="base_link" />
    <child link="imu_link" />
    <origin xyz="0 0 0.30" />
  </joint>

  <link name="imu_link">
    <visual>
      <origin xyz="0 0 0.0" rpy="0 0 0" />
      <geometry>
        <box size="0.02 0.02 0.02" />
      </geometry>
    </visual>
  </link>


  <link name="left_wheel_link">
    <visual>
      <origin xyz="0 0 0" rpy="1.57079 0 0" />
      <geometry>
        <cylinder length="0.05" radius="0.27" />
      </geometry>
      <material name="black">
        <color rgba="0.0 0.0 0.0 0.5" />
      </material>
    </visual>
    <collision>
      <origin xyz="0 0 0" rpy="0 0 0" />
      <geometry>
        <cylinder length="0.2" radius="0.27" />
      </geometry>
    </collision>
  </link>

  <joint name="left_wheel_joint" type="continuous">
    <parent link="base_link" />
    <child link="left_wheel_link" />
    <origin xyz="-0.24 0.27 -0.27" />
    <axis xyz="0 1 0" />
  </joint>

  <link name="right_wheel_link">
    <visual>
      <origin xyz="0 0 0" rpy="1.57079 0 0" />
      <geometry>
        <cylinder length="0.05" radius="0.27" />
      </geometry>
      <material name="black">
        <color rgba="0.0 0.0 0.0 0.5" />
      </material>
    </visual>
    <collision>
      <origin xyz="0 0 0" rpy="0 0 0" />
      <geometry>
        <cylinder length="0.2" radius="0.27" />
      </geometry>
    </collision>
  </link>

  <joint name="right_wheel_joint" type="continuous">
    <parent link="base_link" />
    <child link="right_wheel_link" />
    <origin xyz="-0.24 -0.27 -0.27" />
    <axis xyz="0 1 0" />
  </joint>


  <link name="left_small_wheel_link">
    <visual>
      <origin xyz="0 0 0" rpy="1.57079 0 0" />
      <geometry>
        <cylinder length="0.04" radius="0.12" />
      </geometry>
      <material name="black">
        <color rgba="0.0 0.0 0.0 0.5" />
      </material>
    </visual>
    <collision>
      <origin xyz="0 0 0" rpy="0 0 0" />
      <geometry>
        <cylinder length="0.2" radius="0.12" />
      </geometry>
    </collision>
  </link>

  <joint name="left_small_wheel_joint" type="continuous">
    <parent link="base_link" />
    <child link="left_small_wheel_link" />
    <origin xyz="0.40 0.27 -0.42" />
    <axis xyz="0 1 0" />
  </joint>

  <link name="right_small_wheel_link">
    <visual>
      <origin xyz="0 0 0" rpy="1.57079 0 0" />
      <geometry>
        <cylinder length="0.04" radius="0.12" />
      </geometry>
      <material name="black">
        <color rgba="0.0 0.0 0.0 0.5" />
      </material>
    </visual>
    <collision>
      <origin xyz="0 0 0" rpy="0 0 0" />
      <geometry>
        <cylinder length="0.2" radius="0.12" />
      </geometry>
    </collision>
  </link>

  <joint name="right_small_wheel_joint" type="continuous">
    <parent link="base_link" />
    <child link="right_small_wheel_link" />
    <origin xyz="0.40 -0.27 -0.42" />
    <axis xyz="0 1 0" />
  </joint>


  <!-- <link name="caster_link">
    <visual>
      <origin xyz="0 0 0" rpy="1.57079 0 0"/>
      <geometry>
          <sphere radius="0.016"/>
      </geometry>
        <material name="black">
          <color rgba="0.0 0.0 0.0 0.5" /> 
        </material>
    </visual>
  </link>
    
  <joint name="caster_joint" type="fixed">
      <parent link="base_link" />
      <child link="caster_link" />
      <origin xyz="0.06 0.0 -0.076" />
      <axis xyz="0 1 0" />
  </joint> -->


</robot>